Workbook
Name Deadline: 'Executive Dashboard'!$N$7
Name ProjectStart: Lists!$M$2
Name StatusDate: 'Executive Dashboard'!$H$7

Sheet Executive Dashboard
A1: ALTIJARA MAGAZINE TRANSFORMATION · EXECUTIVE DASHBOARD
A2: Client: O2 Nations · Solo Full-Stack Developer · Build 12–25 Oct · QA & Deployment Prep 26–31 Oct · Final deadline 1 Nov 2026
B3: Production (do not touch): | E3: https://altijaramagazine.com/ | J3: Staging (all work here): | M3: https://chocolate-jellyfish-822708.hostingersite.com/
B4: Go to ▸ | C4: Master | D4: P1 | E4: P2 | F4: P3 | G4: P4 | H4: P5 | I4: P6 | J4: QA | K4: Deploy | L4: Risks | M4: Req Map
B6: CONTROL PANEL (yellow cells are editable — everything else is calculated)
B7: Status date override | F7: Effective status date | H7: =IF(D7="",TODAY(),D7) -> 46306 | L7: Final deadline | N7: 46327
B9: PROGRESS OVERVIEW
B10: OVERALL COMPLETION | E10: PLANNED BY STATUS DATE | H10: SCHEDULE VARIANCE | K10: DAYS TO 1 NOV | N10: SCHEDULE HEALTH
B11: =IFERROR(SUMPRODUCT(('Master Tracker'!$A$6:$A$400<>"")*'Master Tracker'!$U$6:$U$400)/COUNTIF('Master Tracker'!$A$6:$A$400,"?*"),0) -> 0.018018018 | E11: =IFERROR(SUMPRODUCT(('Master Tracker'!$A$6:$A$400<>"")*'Master Tracker'!$V$6:$V$400)/COUNTIF('Master Tracker'!$A$6:$A$400,"?*"),0) -> 0 | H11: =B11-E11 -> 0.018018018 | K11: =Deadline-StatusDate -> 21 | N11: =IF(OR(N16>0,L16>0),"AT RISK",IF(B11-E11<-0.05,"BEHIND","ON TRACK")) -> ON TRACK
B12: average task completion | E12: baseline schedule | H12: actual − planned | K12: calendar days | N12: overdue, blocked & variance
B13: ="Overall "&REPT("█",ROUND(B11*60,0))&REPT("░",60-ROUND(B11*60,0))&" "&TEXT(B11,"0%")&" | Planned "&TEXT(E11,"0%") -> Overall █░░░░░░░░░░░░░░░░░░░░░░░░░░░░░░░░░░░░░░░░░░░░░░░░░░░░░░░░░░░ 2% | Planned 0%
B15: TOTAL TASKS | D15: COMPLETED | F15: IN PROGRESS | H15: NOT STARTED | J15: REVIEW / TESTING | L15: BLOCKED | N15: OVERDUE | P15: OPEN P0
B16: =COUNTIF('Master Tracker'!$A$6:$A$400,"?*") -> 111 | D16: =COUNTIFS('Master Tracker'!$G$6:$G$400,"Completed",'Master Tracker'!$A$6:$A$400,"?*") -> 2 | F16: =COUNTIFS('Master Tracker'!$G$6:$G$400,"In Progress",'Master Tracker'!$A$6:$A$400,"?*") -> 0 | H16: =COUNTIFS('Master Tracker'!$G$6:$G$400,"Not Started",'Master Tracker'!$A$6:$A$400,"?*") -> 109 | J16: =COUNTIFS('Master Tracker'!$G$6:$G$400,"In Review",'Master Tracker'!$A$6:$A$400,"?*")+COUNTIFS('Master Tracker'!$G$6:$G$400,"Testing",'Master Tracker'!$A$6:$A$400,"?*") -> 0 | L16: =COUNTIFS('Master Tracker'!$G$6:$G$400,"Blocked",'Master Tracker'!$A$6:$A$400,"?*") -> 0 | N16: =COUNTIF('Master Tracker'!$X$6:$X$400,"OVERDUE") -> 0 | P16: =COUNTIFS('Master Tracker'!$F$6:$F$400,"P0",'Master Tracker'!$G$6:$G$400,"<>Completed",'Master Tracker'!$A$6:$A$400,"?*") -> 71
B17: in scope | D17: =IF($B$16=0,"",TEXT(D16/$B$16,"0%")&" of tasks") -> 2% of tasks | F17: =IF($B$16=0,"",TEXT(F16/$B$16,"0%")&" of tasks") -> 0% of tasks | H17: =IF($B$16=0,"",TEXT(H16/$B$16,"0%")&" of tasks") -> 98% of tasks | J17: =IF($B$16=0,"",TEXT(J16/$B$16,"0%")&" of tasks") -> 0% of tasks | L17: =IF($B$16=0,"",TEXT(L16/$B$16,"0%")&" of tasks") -> 0% of tasks | N17: =IF($B$16=0,"",TEXT(N16/$B$16,"0%")&" of tasks") -> 0% of tasks | P17: =IF($B$16=0,"",TEXT(P16/$B$16,"0%")&" of tasks") -> 64% of tasks
B19: PHASE PROGRESS (click a phase name to open its tracker)
B20: Phase | C20: Phase name | F20: Window | G20: Tasks | H20: Done | I20: Blocked | J20: Overdue | K20: In Prog. | L20: Open P0 | M20: Planned % | N20: Actual % | O20: Progress | Q20: Health
B21: P1 | C21: Theme Foundation & Asset Pipeline | F21: =TEXT(_xlfn.MINIFS('Master Tracker'!$H$6:$H$400,'Master Tracker'!$B$6:$B$400,"Phase 1"),"dd mmm")&" – "&TEXT(_xlfn.MAXIFS('Master Tracker'!$I$6:$I$400,'Master Tracker'!$B$6:$B$400,"Phase 1"),"dd mmm") -> 12 Oct – 14 Oct | G21: =COUNTIFS('Master Tracker'!$B$6:$B$400,"Phase 1",'Master Tracker'!$A$6:$A$400,"?*") -> 17 | H21: =COUNTIFS('Master Tracker'!$B$6:$B$400,"Phase 1",'Master Tracker'!$G$6:$G$400,"Completed") -> 2 | I21: =COUNTIFS('Master Tracker'!$B$6:$B$400,"Phase 1",'Master Tracker'!$G$6:$G$400,"Blocked") -> 0 | J21: =COUNTIFS('Master Tracker'!$B$6:$B$400,"Phase 1",'Master Tracker'!$X$6:$X$400,"OVERDUE") -> 0 | K21: =COUNTIFS('Master Tracker'!$B$6:$B$400,"Phase 1",'Master Tracker'!$G$6:$G$400,"In Progress") -> 0 | L21: =COUNTIFS('Master Tracker'!$B$6:$B$400,"Phase 1",'Master Tracker'!$F$6:$F$400,"P0",'Master Tracker'!$G$6:$G$400,"<>Completed",'Master Tracker'!$A$6:$A$400,"?*") -> 12 | M21: =IFERROR(SUMPRODUCT(('Master Tracker'!$B$6:$B$400="Phase 1")*'Master Tracker'!$V$6:$V$400)/G21,0) -> 0 | N21: =IFERROR(SUMPRODUCT(('Master Tracker'!$B$6:$B$400="Phase 1")*'Master Tracker'!$U$6:$U$400)/G21,0) -> 0.11764706 | O21: =REPT("█",ROUND(N21*14,0))&REPT("░",14-ROUND(N21*14,0)) -> ██░░░░░░░░░░░░ | Q21: =IF(G21=0,"—",IF(H21=G21,"Complete",IF(I21>0,"Blocked",IF(J21>0,"Behind",IF(N21+0.1<M21,"Behind",IF(N21>0,"On Track","Not Started")))))) -> On Track
B22: P2 | C22: Homepage & Dynamic Section Manager | F22: =TEXT(_xlfn.MINIFS('Master Tracker'!$H$6:$H$400,'Master Tracker'!$B$6:$B$400,"Phase 2"),"dd mmm")&" – "&TEXT(_xlfn.MAXIFS('Master Tracker'!$I$6:$I$400,'Master Tracker'!$B$6:$B$400,"Phase 2"),"dd mmm") -> 15 Oct – 17 Oct | G22: =COUNTIFS('Master Tracker'!$B$6:$B$400,"Phase 2",'Master Tracker'!$A$6:$A$400,"?*") -> 24 | H22: =COUNTIFS('Master Tracker'!$B$6:$B$400,"Phase 2",'Master Tracker'!$G$6:$G$400,"Completed") -> 0 | I22: =COUNTIFS('Master Tracker'!$B$6:$B$400,"Phase 2",'Master Tracker'!$G$6:$G$400,"Blocked") -> 0 | J22: =COUNTIFS('Master Tracker'!$B$6:$B$400,"Phase 2",'Master Tracker'!$X$6:$X$400,"OVERDUE") -> 0 | K22: =COUNTIFS('Master Tracker'!$B$6:$B$400,"Phase 2",'Master Tracker'!$G$6:$G$400,"In Progress") -> 0 | L22: =COUNTIFS('Master Tracker'!$B$6:$B$400,"Phase 2",'Master Tracker'!$F$6:$F$400,"P0",'Master Tracker'!$G$6:$G$400,"<>Completed",'Master Tracker'!$A$6:$A$400,"?*") -> 11 | M22: =IFERROR(SUMPRODUCT(('Master Tracker'!$B$6:$B$400="Phase 2")*'Master Tracker'!$V$6:$V$400)/G22,0) -> 0 | N22: =IFERROR(SUMPRODUCT(('Master Tracker'!$B$6:$B$400="Phase 2")*'Master Tracker'!$U$6:$U$400)/G22,0) -> 0 | O22: =REPT("█",ROUND(N22*14,0))&REPT("░",14-ROUND(N22*14,0)) -> ░░░░░░░░░░░░░░ | Q22: =IF(G22=0,"—",IF(H22=G22,"Complete",IF(I22>0,"Blocked",IF(J22>0,"Behind",IF(N22+0.1<M22,"Behind",IF(N22>0,"On Track","Not Started")))))) -> Not Started
B23: P3 | C23: Editorial & Taxonomy Templates | F23: =TEXT(_xlfn.MINIFS('Master Tracker'!$H$6:$H$400,'Master Tracker'!$B$6:$B$400,"Phase 3"),"dd mmm")&" – "&TEXT(_xlfn.MAXIFS('Master Tracker'!$I$6:$I$400,'Master Tracker'!$B$6:$B$400,"Phase 3"),"dd mmm") -> 18 Oct – 20 Oct | G23: =COUNTIFS('Master Tracker'!$B$6:$B$400,"Phase 3",'Master Tracker'!$A$6:$A$400,"?*") -> 16 | H23: =COUNTIFS('Master Tracker'!$B$6:$B$400,"Phase 3",'Master Tracker'!$G$6:$G$400,"Completed") -> 0 | I23: =COUNTIFS('Master Tracker'!$B$6:$B$400,"Phase 3",'Master Tracker'!$G$6:$G$400,"Blocked") -> 0 | J23: =COUNTIFS('Master Tracker'!$B$6:$B$400,"Phase 3",'Master Tracker'!$X$6:$X$400,"OVERDUE") -> 0 | K23: =COUNTIFS('Master Tracker'!$B$6:$B$400,"Phase 3",'Master Tracker'!$G$6:$G$400,"In Progress") -> 0 | L23: =COUNTIFS('Master Tracker'!$B$6:$B$400,"Phase 3",'Master Tracker'!$F$6:$F$400,"P0",'Master Tracker'!$G$6:$G$400,"<>Completed",'Master Tracker'!$A$6:$A$400,"?*") -> 8 | M23: =IFERROR(SUMPRODUCT(('Master Tracker'!$B$6:$B$400="Phase 3")*'Master Tracker'!$V$6:$V$400)/G23,0) -> 0 | N23: =IFERROR(SUMPRODUCT(('Master Tracker'!$B$6:$B$400="Phase 3")*'Master Tracker'!$U$6:$U$400)/G23,0) -> 0 | O23: =REPT("█",ROUND(N23*14,0))&REPT("░",14-ROUND(N23*14,0)) -> ░░░░░░░░░░░░░░ | Q23: =IF(G23=0,"—",IF(H23=G23,"Complete",IF(I23>0,"Blocked",IF(J23>0,"Behind",IF(N23+0.1<M23,"Behind",IF(N23>0,"On Track","Not Started")))))) -> Not Started
B24: P4 | C24: Digital Issues Archive & CPT Engine | F24: =TEXT(_xlfn.MINIFS('Master Tracker'!$H$6:$H$400,'Master Tracker'!$B$6:$B$400,"Phase 4"),"dd mmm")&" – "&TEXT(_xlfn.MAXIFS('Master Tracker'!$I$6:$I$400,'Master Tracker'!$B$6:$B$400,"Phase 4"),"dd mmm") -> 12 Oct – 22 Oct | G24: =COUNTIFS('Master Tracker'!$B$6:$B$400,"Phase 4",'Master Tracker'!$A$6:$A$400,"?*") -> 12 | H24: =COUNTIFS('Master Tracker'!$B$6:$B$400,"Phase 4",'Master Tracker'!$G$6:$G$400,"Completed") -> 0 | I24: =COUNTIFS('Master Tracker'!$B$6:$B$400,"Phase 4",'Master Tracker'!$G$6:$G$400,"Blocked") -> 0 | J24: =COUNTIFS('Master Tracker'!$B$6:$B$400,"Phase 4",'Master Tracker'!$X$6:$X$400,"OVERDUE") -> 0 | K24: =COUNTIFS('Master Tracker'!$B$6:$B$400,"Phase 4",'Master Tracker'!$G$6:$G$400,"In Progress") -> 0 | L24: =COUNTIFS('Master Tracker'!$B$6:$B$400,"Phase 4",'Master Tracker'!$F$6:$F$400,"P0",'Master Tracker'!$G$6:$G$400,"<>Completed",'Master Tracker'!$A$6:$A$400,"?*") -> 9 | M24: =IFERROR(SUMPRODUCT(('Master Tracker'!$B$6:$B$400="Phase 4")*'Master Tracker'!$V$6:$V$400)/G24,0) -> 0 | N24: =IFERROR(SUMPRODUCT(('Master Tracker'!$B$6:$B$400="Phase 4")*'Master Tracker'!$U$6:$U$400)/G24,0) -> 0 | O24: =REPT("█",ROUND(N24*14,0))&REPT("░",14-ROUND(N24*14,0)) -> ░░░░░░░░░░░░░░ | Q24: =IF(G24=0,"—",IF(H24=G24,"Complete",IF(I24>0,"Blocked",IF(J24>0,"Behind",IF(N24+0.1<M24,"Behind",IF(N24>0,"On Track","Not Started")))))) -> Not Started
B25: P5 | C25: Auth, Subscriptions, AdOps & Leads | F25: =TEXT(_xlfn.MINIFS('Master Tracker'!$H$6:$H$400,'Master Tracker'!$B$6:$B$400,"Phase 5"),"dd mmm")&" – "&TEXT(_xlfn.MAXIFS('Master Tracker'!$I$6:$I$400,'Master Tracker'!$B$6:$B$400,"Phase 5"),"dd mmm") -> 12 Oct – 25 Oct | G25: =COUNTIFS('Master Tracker'!$B$6:$B$400,"Phase 5",'Master Tracker'!$A$6:$A$400,"?*") -> 20 | H25: =COUNTIFS('Master Tracker'!$B$6:$B$400,"Phase 5",'Master Tracker'!$G$6:$G$400,"Completed") -> 0 | I25: =COUNTIFS('Master Tracker'!$B$6:$B$400,"Phase 5",'Master Tracker'!$G$6:$G$400,"Blocked") -> 0 | J25: =COUNTIFS('Master Tracker'!$B$6:$B$400,"Phase 5",'Master Tracker'!$X$6:$X$400,"OVERDUE") -> 0 | K25: =COUNTIFS('Master Tracker'!$B$6:$B$400,"Phase 5",'Master Tracker'!$G$6:$G$400,"In Progress") -> 0 | L25: =COUNTIFS('Master Tracker'!$B$6:$B$400,"Phase 5",'Master Tracker'!$F$6:$F$400,"P0",'Master Tracker'!$G$6:$G$400,"<>Completed",'Master Tracker'!$A$6:$A$400,"?*") -> 11 | M25: =IFERROR(SUMPRODUCT(('Master Tracker'!$B$6:$B$400="Phase 5")*'Master Tracker'!$V$6:$V$400)/G25,0) -> 0 | N25: =IFERROR(SUMPRODUCT(('Master Tracker'!$B$6:$B$400="Phase 5")*'Master Tracker'!$U$6:$U$400)/G25,0) -> 0 | O25: =REPT("█",ROUND(N25*14,0))&REPT("░",14-ROUND(N25*14,0)) -> ░░░░░░░░░░░░░░ | Q25: =IF(G25=0,"—",IF(H25=G25,"Complete",IF(I25>0,"Blocked",IF(J25>0,"Behind",IF(N25+0.1<M25,"Behind",IF(N25>0,"On Track","Not Started")))))) -> Not Started
B26: P6 | C26: Database Cleanup, Crawl Audit & Cutover | F26: =TEXT(_xlfn.MINIFS('Master Tracker'!$H$6:$H$400,'Master Tracker'!$B$6:$B$400,"Phase 6"),"dd mmm")&" – "&TEXT(_xlfn.MAXIFS('Master Tracker'!$I$6:$I$400,'Master Tracker'!$B$6:$B$400,"Phase 6"),"dd mmm") -> 12 Oct – 01 Nov | G26: =COUNTIFS('Master Tracker'!$B$6:$B$400,"Phase 6",'Master Tracker'!$A$6:$A$400,"?*") -> 22 | H26: =COUNTIFS('Master Tracker'!$B$6:$B$400,"Phase 6",'Master Tracker'!$G$6:$G$400,"Completed") -> 0 | I26: =COUNTIFS('Master Tracker'!$B$6:$B$400,"Phase 6",'Master Tracker'!$G$6:$G$400,"Blocked") -> 0 | J26: =COUNTIFS('Master Tracker'!$B$6:$B$400,"Phase 6",'Master Tracker'!$X$6:$X$400,"OVERDUE") -> 0 | K26: =COUNTIFS('Master Tracker'!$B$6:$B$400,"Phase 6",'Master Tracker'!$G$6:$G$400,"In Progress") -> 0 | L26: =COUNTIFS('Master Tracker'!$B$6:$B$400,"Phase 6",'Master Tracker'!$F$6:$F$400,"P0",'Master Tracker'!$G$6:$G$400,"<>Completed",'Master Tracker'!$A$6:$A$400,"?*") -> 20 | M26: =IFERROR(SUMPRODUCT(('Master Tracker'!$B$6:$B$400="Phase 6")*'Master Tracker'!$V$6:$V$400)/G26,0) -> 0 | N26: =IFERROR(SUMPRODUCT(('Master Tracker'!$B$6:$B$400="Phase 6")*'Master Tracker'!$U$6:$U$400)/G26,0) -> 0 | O26: =REPT("█",ROUND(N26*14,0))&REPT("░",14-ROUND(N26*14,0)) -> ░░░░░░░░░░░░░░ | Q26: =IF(G26=0,"—",IF(H26=G26,"Complete",IF(I26>0,"Blocked",IF(J26>0,"Behind",IF(N26+0.1<M26,"Behind",IF(N26>0,"On Track","Not Started")))))) -> Not Started
B27: TOTAL | G27: =SUM(G21:G26) -> 111 | H27: =SUM(H21:H26) -> 2 | I27: =SUM(I21:I26) -> 0 | J27: =SUM(J21:J26) -> 0 | K27: =SUM(K21:K26) -> 0 | L27: =SUM(L21:L26) -> 71 | M27: =E11 -> 0 | N27: =B11 -> 0.018018018
B29: PRIORITY BREAKDOWN | J29: STATUS MIX | N29: OPEN EXTERNAL DEPENDENCIES
B30: Priority | E30: Tasks | F30: Completed | G30: Open | H30: % Done | J30: Status | K30: Count | L30: % | N30: Type | P30: Open | Q30: Next due
B31: P0 · Must-have for launch | E31: =COUNTIFS('Master Tracker'!$F$6:$F$400,"P0",'Master Tracker'!$A$6:$A$400,"?*") -> 73 | F31: =COUNTIFS('Master Tracker'!$F$6:$F$400,"P0",'Master Tracker'!$G$6:$G$400,"Completed") -> 2 | G31: =E31-F31 -> 71 | H31: =IFERROR(F31/E31,0) -> 0.02739726 | J31: Not Started | K31: =COUNTIFS('Master Tracker'!$G$6:$G$400,"Not Started",'Master Tracker'!$A$6:$A$400,"?*") -> 109 | L31: =IFERROR(K31/$B$16,0) -> 0.98198198 | N31: Credentials | P31: =COUNTIFS('Master Tracker'!$S$6:$S$400,"Credentials",'Master Tracker'!$G$6:$G$400,"<>Completed",'Master Tracker'!$A$6:$A$400,"?*") -> 6 | Q31: =IF(P31=0,"—",_xlfn.MINIFS('Master Tracker'!$I$6:$I$400,'Master Tracker'!$S$6:$S$400,"Credentials",'Master Tracker'!$G$6:$G$400,"<>Completed")) -> 46308
B32: P1 · Important | E32: =COUNTIFS('Master Tracker'!$F$6:$F$400,"P1",'Master Tracker'!$A$6:$A$400,"?*") -> 34 | F32: =COUNTIFS('Master Tracker'!$F$6:$F$400,"P1",'Master Tracker'!$G$6:$G$400,"Completed") -> 0 | G32: =E32-F32 -> 34 | H32: =IFERROR(F32/E32,0) -> 0 | J32: In Progress | K32: =COUNTIFS('Master Tracker'!$G$6:$G$400,"In Progress",'Master Tracker'!$A$6:$A$400,"?*") -> 0 | L32: =IFERROR(K32/$B$16,0) -> 0 | N32: Payment Approval | P32: =COUNTIFS('Master Tracker'!$S$6:$S$400,"Payment Approval",'Master Tracker'!$G$6:$G$400,"<>Completed",'Master Tracker'!$A$6:$A$400,"?*") -> 3 | Q32: =IF(P32=0,"—",_xlfn.MINIFS('Master Tracker'!$I$6:$I$400,'Master Tracker'!$S$6:$S$400,"Payment Approval",'Master Tracker'!$G$6:$G$400,"<>Completed")) -> 46317
B33: P2 · Nice-to-have / deferrable | E33: =COUNTIFS('Master Tracker'!$F$6:$F$400,"P2",'Master Tracker'!$A$6:$A$400,"?*") -> 4 | F33: =COUNTIFS('Master Tracker'!$F$6:$F$400,"P2",'Master Tracker'!$G$6:$G$400,"Completed") -> 0 | G33: =E33-F33 -> 4 | H33: =IFERROR(F33/E33,0) -> 0 | J33: Blocked | K33: =COUNTIFS('Master Tracker'!$G$6:$G$400,"Blocked",'Master Tracker'!$A$6:$A$400,"?*") -> 0 | L33: =IFERROR(K33/$B$16,0) -> 0 | N33: Historical Assets | P33: =COUNTIFS('Master Tracker'!$S$6:$S$400,"Historical Assets",'Master Tracker'!$G$6:$G$400,"<>Completed",'Master Tracker'!$A$6:$A$400,"?*") -> 1 | Q33: =IF(P33=0,"—",_xlfn.MINIFS('Master Tracker'!$I$6:$I$400,'Master Tracker'!$S$6:$S$400,"Historical Assets",'Master Tracker'!$G$6:$G$400,"<>Completed")) -> 46315
J34: In Review | K34: =COUNTIFS('Master Tracker'!$G$6:$G$400,"In Review",'Master Tracker'!$A$6:$A$400,"?*") -> 0 | L34: =IFERROR(K34/$B$16,0) -> 0 | N34: Server Access | P34: =COUNTIFS('Master Tracker'!$S$6:$S$400,"Server Access",'Master Tracker'!$G$6:$G$400,"<>Completed",'Master Tracker'!$A$6:$A$400,"?*") -> 9 | Q34: =IF(P34=0,"—",_xlfn.MINIFS('Master Tracker'!$I$6:$I$400,'Master Tracker'!$S$6:$S$400,"Server Access",'Master Tracker'!$G$6:$G$400,"<>Completed")) -> 46307
B35: =IF(N16+L16=0,"✓ No overdue or blocked tasks.","⚠ "&N16&" overdue and "&L16&" blocked task(s). See the lists below and the Master Tracker Alert column.") -> ✓ No overdue or blocked tasks. | J35: Testing | K35: =COUNTIFS('Master Tracker'!$G$6:$G$400,"Testing",'Master Tracker'!$A$6:$A$400,"?*") -> 0 | L35: =IFERROR(K35/$B$16,0) -> 0 | N35: Client Content | P35: =COUNTIFS('Master Tracker'!$S$6:$S$400,"Client Content",'Master Tracker'!$G$6:$G$400,"<>Completed",'Master Tracker'!$A$6:$A$400,"?*") -> 4 | Q35: =IF(P35=0,"—",_xlfn.MINIFS('Master Tracker'!$I$6:$I$400,'Master Tracker'!$S$6:$S$400,"Client Content",'Master Tracker'!$G$6:$G$400,"<>Completed")) -> 46320
J36: Completed | K36: =COUNTIFS('Master Tracker'!$G$6:$G$400,"Completed",'Master Tracker'!$A$6:$A$400,"?*") -> 2 | L36: =IFERROR(K36/$B$16,0) -> 0.018018018
J37: Overdue | K37: =N16 -> 0 | L37: =IFERROR(K37/$B$16,0) -> 0
B40: CHARTS (update automatically from the Master Tracker)
B58: UPCOMING DEADLINES (next open tasks by due date) | K58: CRITICAL BLOCKERS (Blocked status or blocker text)
B59: ID | C59: Task | F59: Phase | G59: Due | H59: Days | I59: Status | K59: ID | L59: Task | N59: Status | O59: Blocker / Issue
B60: =IF($S60="","",INDEX('Master Tracker'!$A$6:$A$400,$S60)) -> P1-03 | C60: =IF($S60="","",INDEX('Master Tracker'!$D$6:$D$400,$S60)) -> Theme setup: supports, menus, image sizes | F60: =IF($S60="","",INDEX('Master Tracker'!$B$6:$B$400,$S60)) -> Phase 1 | G60: =IF($S60="","",INDEX('Master Tracker'!$I$6:$I$400,$S60)) -> 46307 | H60: =IF($S60="","",INDEX('Master Tracker'!$W$6:$W$400,$S60)) -> 1 | I60: =IF($S60="","",INDEX('Master Tracker'!$G$6:$G$400,$S60)) -> Not Started | K60: =IF($T60="","",INDEX('Master Tracker'!$A:$A,$T60)) | L60: =IF($T60="","",INDEX('Master Tracker'!$D:$D,$T60)) | N60: =IF($T60="","",INDEX('Master Tracker'!$G:$G,$T60)) | O60: =IF($T60="","",INDEX('Master Tracker'!$P:$P,$T60)) | S60: =IFERROR(MATCH(SMALL('Master Tracker'!$AA$6:$AA$400,1),'Master Tracker'!$AA$6:$AA$400,0),"") -> 3 | T60: =IFERROR(SMALL('Master Tracker'!$AB$6:$AB$400,1),"")
B61: =IF($S61="","",INDEX('Master Tracker'!$A$6:$A$400,$S61)) -> P1-04 | C61: =IF($S61="","",INDEX('Master Tracker'!$D$6:$D$400,$S61)) -> Asset enqueue, versioning & conditional loading | F61: =IF($S61="","",INDEX('Master Tracker'!$B$6:$B$400,$S61)) -> Phase 1 | G61: =IF($S61="","",INDEX('Master Tracker'!$I$6:$I$400,$S61)) -> 46307 | H61: =IF($S61="","",INDEX('Master Tracker'!$W$6:$W$400,$S61)) -> 1 | I61: =IF($S61="","",INDEX('Master Tracker'!$G$6:$G$400,$S61)) -> Not Started | K61: =IF($T61="","",INDEX('Master Tracker'!$A:$A,$T61)) | L61: =IF($T61="","",INDEX('Master Tracker'!$D:$D,$T61)) | N61: =IF($T61="","",INDEX('Master Tracker'!$G:$G,$T61)) | O61: =IF($T61="","",INDEX('Master Tracker'!$P:$P,$T61)) | S61: =IFERROR(MATCH(SMALL('Master Tracker'!$AA$6:$AA$400,2),'Master Tracker'!$AA$6:$AA$400,0),"") -> 4 | T61: =IFERROR(SMALL('Master Tracker'!$AB$6:$AB$400,2),"")
B62: =IF($S62="","",INDEX('Master Tracker'!$A$6:$A$400,$S62)) -> P1-05 | C62: =IF($S62="","",INDEX('Master Tracker'!$D$6:$D$400,$S62)) -> Base template hierarchy | F62: =IF($S62="","",INDEX('Master Tracker'!$B$6:$B$400,$S62)) -> Phase 1 | G62: =IF($S62="","",INDEX('Master Tracker'!$I$6:$I$400,$S62)) -> 46307 | H62: =IF($S62="","",INDEX('Master Tracker'!$W$6:$W$400,$S62)) -> 1 | I62: =IF($S62="","",INDEX('Master Tracker'!$G$6:$G$400,$S62)) -> Not Started | K62: =IF($T62="","",INDEX('Master Tracker'!$A:$A,$T62)) | L62: =IF($T62="","",INDEX('Master Tracker'!$D:$D,$T62)) | N62: =IF($T62="","",INDEX('Master Tracker'!$G:$G,$T62)) | O62: =IF($T62="","",INDEX('Master Tracker'!$P:$P,$T62)) | S62: =IFERROR(MATCH(SMALL('Master Tracker'!$AA$6:$AA$400,3),'Master Tracker'!$AA$6:$AA$400,0),"") -> 5 | T62: =IFERROR(SMALL('Master Tracker'!$AB$6:$AB$400,3),"")
B63: =IF($S63="","",INDEX('Master Tracker'!$A$6:$A$400,$S63)) -> P1-06 | C63: =IF($S63="","",INDEX('Master Tracker'!$D$6:$D$400,$S63)) -> Reusable template-part components | F63: =IF($S63="","",INDEX('Master Tracker'!$B$6:$B$400,$S63)) -> Phase 1 | G63: =IF($S63="","",INDEX('Master Tracker'!$I$6:$I$400,$S63)) -> 46307 | H63: =IF($S63="","",INDEX('Master Tracker'!$W$6:$W$400,$S63)) -> 1 | I63: =IF($S63="","",INDEX('Master Tracker'!$G$6:$G$400,$S63)) -> Not Started | K63: =IF($T63="","",INDEX('Master Tracker'!$A:$A,$T63)) | L63: =IF($T63="","",INDEX('Master Tracker'!$D:$D,$T63)) | N63: =IF($T63="","",INDEX('Master Tracker'!$G:$G,$T63)) | O63: =IF($T63="","",INDEX('Master Tracker'!$P:$P,$T63)) | S63: =IFERROR(MATCH(SMALL('Master Tracker'!$AA$6:$AA$400,4),'Master Tracker'!$AA$6:$AA$400,0),"") -> 6 | T63: =IFERROR(SMALL('Master Tracker'!$AB$6:$AB$400,4),"")
B64: =IF($S64="","",INDEX('Master Tracker'!$A$6:$A$400,$S64)) -> P6-01 | C64: =IF($S64="","",INDEX('Master Tracker'!$D$6:$D$400,$S64)) -> Full production backup (files + DB) before any work | F64: =IF($S64="","",INDEX('Master Tracker'!$B$6:$B$400,$S64)) -> Phase 6 | G64: =IF($S64="","",INDEX('Master Tracker'!$I$6:$I$400,$S64)) -> 46307 | H64: =IF($S64="","",INDEX('Master Tracker'!$W$6:$W$400,$S64)) -> 1 | I64: =IF($S64="","",INDEX('Master Tracker'!$G$6:$G$400,$S64)) -> Not Started | K64: =IF($T64="","",INDEX('Master Tracker'!$A:$A,$T64)) | L64: =IF($T64="","",INDEX('Master Tracker'!$D:$D,$T64)) | N64: =IF($T64="","",INDEX('Master Tracker'!$G:$G,$T64)) | O64: =IF($T64="","",INDEX('Master Tracker'!$P:$P,$T64)) | S64: =IFERROR(MATCH(SMALL('Master Tracker'!$AA$6:$AA$400,5),'Master Tracker'!$AA$6:$AA$400,0),"") -> 90 | T64: =IFERROR(SMALL('Master Tracker'!$AB$6:$AB$400,5),"")
...

Sheet Master Tracker
A1: MASTER PROJECT TRACKER · single source of truth
A2: Edit tasks here only — dashboard, phase sheets and requirement map recalculate automatically.
A3: Legend: | B3: Editable | C3: ƒ Calculated | D3: Status colors → | E3: Completed · In Progress · In Review / Testing · Blocked / Overdue · Not Started | G3: ← Dashboard | I3: Staging ↗ | K3: Live ↗
A5: Task ID | B5: Phase ▾ | C5: Module ▾ | D5: Task Name | E5: Detailed Description | F5: Priority ▾ | G5: Status ▾ | H5: Start Date ▾ | I5: Due Date ▾ | J5: Completion % ▾ | K5: Dependencies ▾ | L5: Environment ▾ | M5: Related WordPress Files | N5: Testing Checklist | O5: Acceptance Criteria | P5: Blocker / Issue ▾ | Q5: Notes ▾ | R5: Completion Date ▾ | S5: External Requirement ▾ | T5: Test Result ▾ | U5: ƒ Effective % | V5: ƒ Planned % | W5: ƒ Days Left | X5: ƒ Overdue | Y5: ƒ Dependency Check | Z5: ƒ Phase Key | AA5: ƒ Upcoming Key | AB5: ƒ Blocker Key | AC5: ƒ Alert
A6: P1-01 | B6: Phase 1 | C6: Staging Setup | D6: Staging environment readiness audit | E6: Confirm Hostinger staging access (hPanel, SFTP/SSH, phpMyAdmin), PHP 8.1+, WordPress & plugin versions, memory limits; enable WP_DEBUG_LOG; block indexing (noindex + password/IP protection); disable or trap outgoing mail so staging never emails real readers. | F6: P0 | G6: Completed | H6: 46307 | I6: 46307 | J6: 0 | K6: P6-02 | L6: Staging (Hostinger) | M6: wp-config.php, .htaccess | N6: Log in via hPanel, SFTP and phpMyAdmin; confirm noindex header; send test mail is trapped | O6: Staging is reachable only by the team, not indexed, debug logging active, versions documented in Notes | S6: Server Access | T6: Not Tested | U6: =IF(A6="",0,IF(G6="Completed",1,IF(G6="Not Started",0,MIN(0.99,N(J6))))) -> 1 | V6: =IF(OR(A6="",H6="",I6=""),0,MAX(0,MIN(1,(StatusDate-H6+1)/(I6-H6+1)))) -> 0 | W6: =IF(OR(A6="",I6="",G6="Completed"),"",I6-StatusDate) | X6: =IF(A6="","",IF(AND(G6<>"Completed",I6<>"",I6<StatusDate),"OVERDUE","")) | Y6: =IF(OR(A6="",K6=""),"",IF(SUMPRODUCT(($A$6:$A$400<>"")*ISNUMBER(SEARCH($A$6:$A$400,K6))*($G$6:$G$400<>"Completed"))=0,"✓ Ready","⏳ "&SUMPRODUCT(($A$6:$A$400<>"")*ISNUMBER(SEARCH($A$6:$A$400,K6))*($G$6:$G$400<>"Completed"))&" open")) -> ⏳ 1 open | Z6: =IF(A6="","",B6&"|"&COUNTIFS($B$6:B6,B6,$A$6:A6,"?*")) -> Phase 1|1 | AA6: =IF(OR(A6="",I6="",G6="Completed"),"",IF(I6>=StatusDate,I6+ROW()/100000,"")) | AB6: =IF(A6="","",IF(AND(G6<>"Completed",OR(G6="Blocked",AND(TRIM(P6)<>"",P6<>"None"))),ROW(),"")) | AC6: =IF(A6="","",IF(G6="Completed","Done",IF(G6="Blocked","Blocked",IF(X6="OVERDUE","Overdue",IF(AND(W6<>"",W6<=2),"Due soon",IF(AND(Y6<>"",LEFT(Y6,1)="⏳",G6<>"Not Started"),"Dependency open",IF(AND(S6<>"None",S6<>"",G6<>"Completed"),"External req.","On track"))))))) -> Done
A7: P1-02 | B7: Phase 1 | C7: Theme Scaffold | D7: Create custom theme structure + Git repo | E7: Create /wp-content/themes/altijara/ with style.css header (Text Domain altijara, RTL), functions.php loader, inc/, template-parts/, assets/{css,js,fonts,img}, languages/. Initialise a remote Git repository for the theme as the backup of all staging work (no local environment). | F7: P0 | G7: Completed | H7: 46307 | I7: 46307 | J7: 0 | K7: P1-01 | L7: Staging (Hostinger) | M7: style.css, functions.php, inc/, template-parts/, assets/ | N7: Theme listed in Appearance > Themes; activates with no PHP notices; first commit pushed | O7: Folder structure in place, theme activates cleanly on staging, repository holds initial commit | S7: None | T7: Not Tested | U7: =IF(A7="",0,IF(G7="Completed",1,IF(G7="Not Started",0,MIN(0.99,N(J7))))) -> 1 | V7: =IF(OR(A7="",H7="",I7=""),0,MAX(0,MIN(1,(StatusDate-H7+1)/(I7-H7+1)))) -> 0 | W7: =IF(OR(A7="",I7="",G7="Completed"),"",I7-StatusDate) | X7: =IF(A7="","",IF(AND(G7<>"Completed",I7<>"",I7<StatusDate),"OVERDUE","")) | Y7: =IF(OR(A7="",K7=""),"",IF(SUMPRODUCT(($A$6:$A$400<>"")*ISNUMBER(SEARCH($A$6:$A$400,K7))*($G$6:$G$400<>"Completed"))=0,"✓ Ready","⏳ "&SUMPRODUCT(($A$6:$A$400<>"")*ISNUMBER(SEARCH($A$6:$A$400,K7))*($G$6:$G$400<>"Completed"))&" open")) -> ✓ Ready | Z7: =IF(A7="","",B7&"|"&COUNTIFS($B$6:B7,B7,$A$6:A7,"?*")) -> Phase 1|2 | AA7: =IF(OR(A7="",I7="",G7="Completed"),"",IF(I7>=StatusDate,I7+ROW()/100000,"")) | AB7: =IF(A7="","",IF(AND(G7<>"Completed",OR(G7="Blocked",AND(TRIM(P7)<>"",P7<>"None"))),ROW(),"")) | AC7: =IF(A7="","",IF(G7="Completed","Done",IF(G7="Blocked","Blocked",IF(X7="OVERDUE","Overdue",IF(AND(W7<>"",W7<=2),"Due soon",IF(AND(Y7<>"",LEFT(Y7,1)="⏳",G7<>"Not Started"),"Dependency open",IF(AND(S7<>"None",S7<>"",G7<>"Completed"),"External req.","On track"))))))) -> Done
A8: P1-03 | B8: Phase 1 | C8: Theme Initialization | D8: Theme setup: supports, menus, image sizes | E8: inc/setup.php: add_theme_support (title-tag, post-thumbnails, html5, custom-logo, responsive-embeds, align-wide, editor-styles); register_nav_menus (primary, top-bar, footer, mobile); add_image_size (hero, card, thumb, issue-cover); load_theme_textdomain; content_width. | F8: P0 | G8: Not Started | H8: 46307 | I8: 46307 | J8: 0 | K8: P1-02 | L8: Staging (Hostinger) | M8: inc/setup.php, functions.php | N8: Menus appear in Appearance > Menus; new upload generates all image sizes; single <title> tag | O8: All supports, menus and image sizes registered; no duplicate title tags | S8: None | T8: Not Tested | U8: =IF(A8="",0,IF(G8="Completed",1,IF(G8="Not Started",0,MIN(0.99,N(J8))))) -> 0 | V8: =IF(OR(A8="",H8="",I8=""),0,MAX(0,MIN(1,(StatusDate-H8+1)/(I8-H8+1)))) -> 0 | W8: =IF(OR(A8="",I8="",G8="Completed"),"",I8-StatusDate) -> 1 | X8: =IF(A8="","",IF(AND(G8<>"Completed",I8<>"",I8<StatusDate),"OVERDUE","")) | Y8: =IF(OR(A8="",K8=""),"",IF(SUMPRODUCT(($A$6:$A$400<>"")*ISNUMBER(SEARCH($A$6:$A$400,K8))*($G$6:$G$400<>"Completed"))=0,"✓ Ready","⏳ "&SUMPRODUCT(($A$6:$A$400<>"")*ISNUMBER(SEARCH($A$6:$A$400,K8))*($G$6:$G$400<>"Completed"))&" open")) -> ✓ Ready | Z8: =IF(A8="","",B8&"|"&COUNTIFS($B$6:B8,B8,$A$6:A8,"?*")) -> Phase 1|3 | AA8: =IF(OR(A8="",I8="",G8="Completed"),"",IF(I8>=StatusDate,I8+ROW()/100000,"")) -> 46307 | AB8: =IF(A8="","",IF(AND(G8<>"Completed",OR(G8="Blocked",AND(TRIM(P8)<>"",P8<>"None"))),ROW(),"")) | AC8: =IF(A8="","",IF(G8="Completed","Done",IF(G8="Blocked","Blocked",IF(X8="OVERDUE","Overdue",IF(AND(W8<>"",W8<=2),"Due soon",IF(AND(Y8<>"",LEFT(Y8,1)="⏳",G8<>"Not Started"),"Dependency open",IF(AND(S8<>"None",S8<>"",G8<>"Completed"),"External req.","On track"))))))) -> Due soon
A9: P1-04 | B9: Phase 1 | C9: Asset Pipeline | D9: Asset enqueue, versioning & conditional loading | E9: inc/enqueue.php: enqueue CSS/JS with filemtime() cache-busting, per-template conditional loading, defer/module attributes, preload primary Arabic font, remove emoji script, no jQuery dependency on the front end. | F9: P0 | G9: Not Started | H9: 46307 | I9: 46307 | J9: 0 | K9: P1-02 | L9: Staging (Hostinger) | M9: inc/enqueue.php, assets/css/*, assets/js/* | N9: View source: versioned URLs, deferred scripts; Network tab shows no 404s and no jQuery on homepage | O9: All assets versioned and loaded only where needed; zero console errors | S9: None | T9: Not Tested | U9: =IF(A9="",0,IF(G9="Completed",1,IF(G9="Not Started",0,MIN(0.99,N(J9))))) -> 0 | V9: =IF(OR(A9="",H9="",I9=""),0,MAX(0,MIN(1,(StatusDate-H9+1)/(I9-H9+1)))) -> 0 | W9: =IF(OR(A9="",I9="",G9="Completed"),"",I9-StatusDate) -> 1 | X9: =IF(A9="","",IF(AND(G9<>"Completed",I9<>"",I9<StatusDate),"OVERDUE","")) | Y9: =IF(OR(A9="",K9=""),"",IF(SUMPRODUCT(($A$6:$A$400<>"")*ISNUMBER(SEARCH($A$6:$A$400,K9))*($G$6:$G$400<>"Completed"))=0,"✓ Ready","⏳ "&SUMPRODUCT(($A$6:$A$400<>"")*ISNUMBER(SEARCH($A$6:$A$400,K9))*($G$6:$G$400<>"Completed"))&" open")) -> ✓ Ready | Z9: =IF(A9="","",B9&"|"&COUNTIFS($B$6:B9,B9,$A$6:A9,"?*")) -> Phase 1|4 | AA9: =IF(OR(A9="",I9="",G9="Completed"),"",IF(I9>=StatusDate,I9+ROW()/100000,"")) -> 46307 | AB9: =IF(A9="","",IF(AND(G9<>"Completed",OR(G9="Blocked",AND(TRIM(P9)<>"",P9<>"None"))),ROW(),"")) | AC9: =IF(A9="","",IF(G9="Completed","Done",IF(G9="Blocked","Blocked",IF(X9="OVERDUE","Overdue",IF(AND(W9<>"",W9<=2),"Due soon",IF(AND(Y9<>"",LEFT(Y9,1)="⏳",G9<>"Not Started"),"Dependency open",IF(AND(S9<>"None",S9<>"",G9<>"Completed"),"External req.","On track"))))))) -> Due soon
A10: P1-05 | B10: Phase 1 | C10: PHP Templates | D10: Base template hierarchy | E10: Create header.php, footer.php, index.php, front-page.php, single.php, page.php, archive.php, category.php, tag.php, author.php, search.php, 404.php skeletons sharing a common layout wrapper. | F10: P0 | G10: Not Started | H10: 46307 | I10: 46307 | J10: 0 | K10: P1-03 | L10: Staging (Hostinger) | M10: header.php, footer.php, index.php, front-page.php, single.php, page.php, archive.php, category.php, tag.php, author.php, search.php, 404.php | N10: Visit each route type; Query Monitor confirms expected template file | O10: Every WordPress route resolves to a theme template with header/footer; no fallback errors | S10: None | T10: Not Tested | U10: =IF(A10="",0,IF(G10="Completed",1,IF(G10="Not Started",0,MIN(0.99,N(J10))))) -> 0 | V10: =IF(OR(A10="",H10="",I10=""),0,MAX(0,MIN(1,(StatusDate-H10+1)/(I10-H10+1)))) -> 0 | W10: =IF(OR(A10="",I10="",G10="Completed"),"",I10-StatusDate) -> 1 | X10: =IF(A10="","",IF(AND(G10<>"Completed",I10<>"",I10<StatusDate),"OVERDUE","")) | Y10: =IF(OR(A10="",K10=""),"",IF(SUMPRODUCT(($A$6:$A$400<>"")*ISNUMBER(SEARCH($A$6:$A$400,K10))*($G$6:$G$400<>"Completed"))=0,"✓ Ready","⏳ "&SUMPRODUCT(($A$6:$A$400<>"")*ISNUMBER(SEARCH($A$6:$A$400,K10))*($G$6:$G$400<>"Completed"))&" open")) -> ⏳ 1 open | Z10: =IF(A10="","",B10&"|"&COUNTIFS($B$6:B10,B10,$A$6:A10,"?*")) -> Phase 1|5 | AA10: =IF(OR(A10="",I10="",G10="Completed"),"",IF(I10>=StatusDate,I10+ROW()/100000,"")) -> 46307 | AB10: =IF(A10="","",IF(AND(G10<>"Completed",OR(G10="Blocked",AND(TRIM(P10)<>"",P10<>"None"))),ROW(),"")) | AC10: =IF(A10="","",IF(G10="Completed","Done",IF(G10="Blocked","Blocked",IF(X10="OVERDUE","Overdue",IF(AND(W10<>"",W10<=2),"Due soon",IF(AND(Y10<>"",LEFT(Y10,1)="⏳",G10<>"Not Started"),"Dependency open",IF(AND(S10<>"None",S10<>"",G10<>"Completed"),"External req.","On track"))))))) -> Due soon
A11: P1-06 | B11: Phase 1 | C11: Components | D11: Reusable template-part components | E11: template-parts/components: card-hero, card-large, card-medium, card-list, card-mini, section-header, post-meta, category-badge, pagination, ad-slot, empty-state. All accept $args via get_template_part() and escape output (esc_html/esc_url/esc_attr). | F11: P0 | G11: Not Started | H11: 46307 | I11: 46307 | J11: 0 | K11: P1-05 | L11: Staging (Hostinger) | M11: template-parts/components/*.php | N11: Render every component on a test page with real posts; test missing image/excerpt; check escaping | O11: Components reused by homepage and archives with no duplicated markup; all output escaped | S11: None | T11: Not Tested | U11: =IF(A11="",0,IF(G11="Completed",1,IF(G11="Not Started",0,MIN(0.99,N(J11))))) -> 0 | V11: =IF(OR(A11="",H11="",I11=""),0,MAX(0,MIN(1,(StatusDate-H11+1)/(I11-H11+1)))) -> 0 | W11: =IF(OR(A11="",I11="",G11="Completed"),"",I11-StatusDate) -> 1 | X11: =IF(A11="","",IF(AND(G11<>"Completed",I11<>"",I11<StatusDate),"OVERDUE","")) | Y11: =IF(OR(A11="",K11=""),"",IF(SUMPRODUCT(($A$6:$A$400<>"")*ISNUMBER(SEARCH($A$6:$A$400,K11))*($G$6:$G$400<>"Completed"))=0,"✓ Ready","⏳ "&SUMPRODUCT(($A$6:$A$400<>"")*ISNUMBER(SEARCH($A$6:$A$400,K11))*($G$6:$G$400<>"Completed"))&" open")) -> ⏳ 1 open | Z11: =IF(A11="","",B11&"|"&COUNTIFS($B$6:B11,B11,$A$6:A11,"?*")) -> Phase 1|6 | AA11: =IF(OR(A11="",I11="",G11="Completed"),"",IF(I11>=StatusDate,I11+ROW()/100000,"")) -> 46307 | AB11: =IF(A11="","",IF(AND(G11<>"Completed",OR(G11="Blocked",AND(TRIM(P11)<>"",P11<>"None"))),ROW(),"")) | AC11: =IF(A11="","",IF(G11="Completed","Done",IF(G11="Blocked","Blocked",IF(X11="OVERDUE","Overdue",IF(AND(W11<>"",W11<=2),"Due soon",IF(AND(Y11<>"",LEFT(Y11,1)="⏳",G11<>"Not Started"),"Dependency open",IF(AND(S11<>"None",S11<>"",G11<>"Completed"),"External req.","On track"))))))) -> Due soon
A12: P1-07 | B12: Phase 1 | C12: CSS Architecture | D12: CSS architecture & design tokens | E12: assets/css: tokens.css (colors, spacing, type scale as custom properties), base, layout, components, utilities, templates. Use CSS logical properties for native RTL. No CSS framework. Minification delegated to LiteSpeed (no local build tooling). | F12: P0 | G12: Not Started | H12: 46307 | I12: 46308 | J12: 0 | K12: P1-04 | L12: Staging (Hostinger) | M12: assets/css/tokens.css, base.css, layout.css, components.css, utilities.css | N12: Inspect computed styles use tokens; RTL correct without separate override file; CSS size checked | O12: Single token source; consistent styling; total CSS within agreed budget (target < 100 KB uncompressed) | S12: None | T12: Not Tested | U12: =IF(A12="",0,IF(G12="Completed",1,IF(G12="Not Started",0,MIN(0.99,N(J12))))) -> 0 | V12: =IF(OR(A12="",H12="",I12=""),0,MAX(0,MIN(1,(StatusDate-H12+1)/(I12-H12+1)))) -> 0 | W12: =IF(OR(A12="",I12="",G12="Completed"),"",I12-StatusDate) -> 2 | X12: =IF(A12="","",IF(AND(G12<>"Completed",I12<>"",I12<StatusDate),"OVERDUE","")) | Y12: =IF(OR(A12="",K12=""),"",IF(SUMPRODUCT(($A$6:$A$400<>"")*ISNUMBER(SEARCH($A$6:$A$400,K12))*($G$6:$G$400<>"Completed"))=0,"✓ Ready","⏳ "&SUMPRODUCT(($A$6:$A$400<>"")*ISNUMBER(SEARCH($A$6:$A$400,K12))*($G$6:$G$400<>"Completed"))&" open")) -> ⏳ 1 open | Z12: =IF(A12="","",B12&"|"&COUNTIFS($B$6:B12,B12,$A$6:A12,"?*")) -> Phase 1|7 | AA12: =IF(OR(A12="",I12="",G12="Completed"),"",IF(I12>=StatusDate,I12+ROW()/100000,"")) -> 46308 | AB12: =IF(A12="","",IF(AND(G12<>"Completed",OR(G12="Blocked",AND(TRIM(P12)<>"",P12<>"None"))),ROW(),"")) | AC12: =IF(A12="","",IF(G12="Completed","Done",IF(G12="Blocked","Blocked",IF(X12="OVERDUE","Overdue",IF(AND(W12<>"",W12<=2),"Due soon",IF(AND(Y12<>"",LEFT(Y12,1)="⏳",G12<>"Not Started"),"Dependency open",IF(AND(S12<>"None",S12<>"",G12<>"Completed"),"External req.","On track"))))))) -> Due soon
A13: P1-08 | B13: Phase 1 | C13: Vanilla JS | D13: Vanilla JS module architecture | E13: assets/js/main.js bootstraps data-attribute driven modules (nav, drawer, search overlay, sticky header); IntersectionObserver utilities; respects prefers-reduced-motion; no jQuery. | F13: P0 | G13: Not Started | H13: 46308 | I13: 46308 | J13: 0 | K13: P1-04 | L13: Staging (Hostinger) | M13: assets/js/main.js, assets/js/modules/*.js | N13: Console clean on Chrome & Safari; page usable with JS disabled | O13: All interactions implemented in Vanilla JS; zero console errors; scripts deferred | S13: None | T13: Not Tested | U13: =IF(A13="",0,IF(G13="Completed",1,IF(G13="Not Started",0,MIN(0.99,N(J13))))) -> 0 | V13: =IF(OR(A13="",H13="",I13=""),0,MAX(0,MIN(1,(StatusDate-H13+1)/(I13-H13+1)))) -> 0 | W13: =IF(OR(A13="",I13="",G13="Completed"),"",I13-StatusDate) -> 2 | X13: =IF(A13="","",IF(AND(G13<>"Completed",I13<>"",I13<StatusDate),"OVERDUE","")) | Y13: =IF(OR(A13="",K13=""),"",IF(SUMPRODUCT(($A$6:$A$400<>"")*ISNUMBER(SEARCH($A$6:$A$400,K13))*($G$6:$G$400<>"Completed"))=0,"✓ Ready","⏳ "&SUMPRODUCT(($A$6:$A$400<>"")*ISNUMBER(SEARCH($A$6:$A$400,K13))*($G$6:$G$400<>"Completed"))&" open")) -> ⏳ 1 open | Z13: =IF(A13="","",B13&"|"&COUNTIFS($B$6:B13,B13,$A$6:A13,"?*")) -> Phase 1|8 | AA13: =IF(OR(A13="",I13="",G13="Completed"),"",IF(I13>=StatusDate,I13+ROW()/100000,"")) -> 46308 | AB13: =IF(A13="","",IF(AND(G13<>"Completed",OR(G13="Blocked",AND(TRIM(P13)<>"",P13<>"None"))),ROW(),"")) | AC13: =IF(A13="","",IF(G13="Completed","Done",IF(G13="Blocked","Blocked",IF(X13="OVERDUE","Overdue",IF(AND(W13<>"",W13<=2),"Due soon",IF(AND(Y13<>"",LEFT(Y13,1)="⏳",G13<>"Not Started"),"Dependency open",IF(AND(S13<>"None",S13<>"",G13<>"Completed"),"External req.","On track"))))))) -> Due soon
A14: P1-09 | B14: Phase 1 | C14: RTL Typography | D14: RTL layout & Arabic typography | E14: html dir='rtl' lang='ar'; self-hosted Arabic WOFF2 fonts (font-display: swap, subset); Arabic-appropriate line-height & type scale; bidi isolation for mixed Arabic/English strings; numerals policy. | F14: P0 | G14: Not Started | H14: 46308 | I14: 46308 | J14: 0 | K14: P1-07 | L14: Staging (Hostinger) | M14: assets/fonts/*, assets/css/base.css, header.php | N14: Headlines/body render in Arabic font on iOS, Android, desktop; no invisible text flash; mixed strings align | O14: Correct RTL direction site-wide; fonts self-hosted; no layout shift from font swap | S14: None | T14: Not Tested | U14: =IF(A14="",0,IF(G14="Completed",1,IF(G14="Not Started",0,MIN(0.99,N(J14))))) -> 0 | V14: =IF(OR(A14="",H14="",I14=""),0,MAX(0,MIN(1,(StatusDate-H14+1)/(I14-H14+1)))) -> 0 | W14: =IF(OR(A14="",I14="",G14="Completed"),"",I14-StatusDate) -> 2 | X14: =IF(A14="","",IF(AND(G14<>"Completed",I14<>"",I14<StatusDate),"OVERDUE","")) | Y14: =IF(OR(A14="",K14=""),"",IF(SUMPRODUCT(($A$6:$A$400<>"")*ISNUMBER(SEARCH($A$6:$A$400,K14))*($G$6:$G$400<>"Completed"))=0,"✓ Ready","⏳ "&SUMPRODUCT(($A$6:$A$400<>"")*ISNUMBER(SEARCH($A$6:$A$400,K14))*($G$6:$G$400<>"Completed"))&" open")) -> ⏳ 1 open | Z14: =IF(A14="","",B14&"|"&COUNTIFS($B$6:B14,B14,$A$6:A14,"?*")) -> Phase 1|9 | AA14: =IF(OR(A14="",I14="",G14="Completed"),"",IF(I14>=StatusDate,I14+ROW()/100000,"")) -> 46308 | AB14: =IF(A14="","",IF(AND(G14<>"Completed",OR(G14="Blocked",AND(TRIM(P14)<>"",P14<>"None"))),ROW(),"")) | AC14: =IF(A14="","",IF(G14="Completed","Done",IF(G14="Blocked","Blocked",IF(X14="OVERDUE","Overdue",IF(AND(W14<>"",W14<=2),"Due soon",IF(AND(Y14<>"",LEFT(Y14,1)="⏳",G14<>"Not Started"),"Dependency open",IF(AND(S14<>"None",S14<>"",G14<>"Completed"),"External req.","On track"))))))) -> Due soon
A15: P1-10 | B15: Phase 1 | C15: Responsive Design | D15: Responsive grid & breakpoints | E15: Mobile-first container and CSS grid; breakpoints 360/576/768/1024/1280+; fluid type with clamp(); responsive images with srcset/sizes. | F15: P0 | G15: Not Started | H15: 46308 | I15: 46308 | J15: 0 | K15: P1-07 | L15: Staging (Hostinger) | M15: assets/css/layout.css | N15: Test 360, 414, 768, 1024, 1440 px widths; no horizontal scroll | O15: All layouts usable at 360 px; no overflow; correctly sized images | S15: None | T15: Not Tested | U15: =IF(A15="",0,IF(G15="Completed",1,IF(G15="Not Started",0,MIN(0.99,N(J15))))) -> 0 | V15: =IF(OR(A15="",H15="",I15=""),0,MAX(0,MIN(1,(StatusDate-H15+1)/(I15-H15+1)))) -> 0 | W15: =IF(OR(A15="",I15="",G15="Completed"),"",I15-StatusDate) -> 2 | X15: =IF(A15="","",IF(AND(G15<>"Completed",I15<>"",I15<StatusDate),"OVERDUE","")) | Y15: =IF(OR(A15="",K15=""),"",IF(SUMPRODUCT(($A$6:$A$400<>"")*ISNUMBER(SEARCH($A$6:$A$400,K15))*($G$6:$G$400<>"Completed"))=0,"✓ Ready","⏳ "&SUMPRODUCT(($A$6:$A$400<>"")*ISNUMBER(SEARCH($A$6:$A$400,K15))*($G$6:$G$400<>"Completed"))&" open")) -> ⏳ 1 open | Z15: =IF(A15="","",B15&"|"&COUNTIFS($B$6:B15,B15,$A$6:A15,"?*")) -> Phase 1|10 | AA15: =IF(OR(A15="",I15="",G15="Completed"),"",IF(I15>=StatusDate,I15+ROW()/100000,"")) -> 46308 | AB15: =IF(A15="","",IF(AND(G15<>"Completed",OR(G15="Blocked",AND(TRIM(P15)<>"",P15<>"None"))),ROW(),"")) | AC15: =IF(A15="","",IF(G15="Completed","Done",IF(G15="Blocked","Blocked",IF(X15="OVERDUE","Overdue",IF(AND(W15<>"",W15<=2),"Due soon",IF(AND(Y15<>"",LEFT(Y15,1)="⏳",G15<>"Not Started"),"Dependency open",IF(AND(S15<>"None",S15<>"",G15<>"Completed"),"External req.","On track"))))))) -> Due soon
A16: P1-11 | B16: Phase 1 | C16: Header & Navigation | D16: Header, navigation, mobile drawer & search | E16: Top bar with Arabic date, custom logo, primary menu with dropdowns, off-canvas mobile drawer, search overlay, sticky header; keyboard and screen-reader accessible. | F16: P0 | G16: Not Started | H16: 46308 | I16: 46309 | J16: 0 | K16: P1-06, P1-08, P1-15 | L16: Staging (Hostinger) | M16: header.php, template-parts/header/*.php, assets/js/modules/nav.js | N16: Drawer opens/closes, Esc closes, focus trapped; search submits; menu edited in WP admin updates header | O16: Navigation works on touch and keyboard; fully managed from WordPress menus | S16: None | T16: Not Tested | U16: =IF(A16="",0,IF(G16="Completed",1,IF(G16="Not Started",0,MIN(0.99,N(J16))))) -> 0 | V16: =IF(OR(A16="",H16="",I16=""),0,MAX(0,MIN(1,(StatusDate-H16+1)/(I16-H16+1)))) -> 0 | W16: =IF(OR(A16="",I16="",G16="Completed"),"",I16-StatusDate) -> 3 | X16: =IF(A16="","",IF(AND(G16<>"Completed",I16<>"",I16<StatusDate),"OVERDUE","")) | Y16: =IF(OR(A16="",K16=""),"",IF(SUMPRODUCT(($A$6:$A$400<>"")*ISNUMBER(SEARCH($A$6:$A$400,K16))*($G$6:$G$400<>"Completed"))=0,"✓ Ready","⏳ "&SUMPRODUCT(($A$6:$A$400<>"")*ISNUMBER(SEARCH($A$6:$A$400,K16))*($G$6:$G$400<>"Completed"))&" open")) -> ⏳ 3 open | Z16: =IF(A16="","",B16&"|"&COUNTIFS($B$6:B16,B16,$A$6:A16,"?*")) -> Phase 1|11 | AA16: =IF(OR(A16="",I16="",G16="Completed"),"",IF(I16>=StatusDate,I16+ROW()/100000,"")) -> 46309 | AB16: =IF(A16="","",IF(AND(G16<>"Completed",OR(G16="Blocked",AND(TRIM(P16)<>"",P16<>"None"))),ROW(),"")) | AC16: =IF(A16="","",IF(G16="Completed","Done",IF(G16="Blocked","Blocked",IF(X16="OVERDUE","Overdue",IF(AND(W16<>"",W16<=2),"Due soon",IF(AND(Y16<>"",LEFT(Y16,1)="⏳",G16<>"Not Started"),"Dependency open",IF(AND(S16<>"None",S16<>"",G16<>"Completed"),"External req.","On track"))))))) -> On track
A17: P1-12 | B17: Phase 1 | C17: Footer | D17: Footer with editable menus & social links | E17: Footer menus, social links via Customizer, newsletter/CTA slot, copyright, back-to-top. | F17: P1 | G17: Not Started | H17: 46309 | I17: 46309 | J17: 0 | K17: P1-06 | L17: Staging (Hostinger) | M17: footer.php, template-parts/footer/*.php | N17: All links resolve; social URLs editable in Customizer | O17: Footer content editable without code | S17: None | T17: Not Tested | U17: =IF(A17="",0,IF(G17="Completed",1,IF(G17="Not Started",0,MIN(0.99,N(J17))))) -> 0 | V17: =IF(OR(A17="",H17="",I17=""),0,MAX(0,MIN(1,(StatusDate-H17+1)/(I17-H17+1)))) -> 0 | W17: =IF(OR(A17="",I17="",G17="Completed"),"",I17-StatusDate) -> 3 | X17: =IF(A17="","",IF(AND(G17<>"Completed",I17<>"",I17<StatusDate),"OVERDUE","")) | Y17: =IF(OR(A17="",K17=""),"",IF(SUMPRODUCT(($A$6:$A$400<>"")*ISNUMBER(SEARCH($A$6:$A$400,K17))*($G$6:$G$400<>"Completed"))=0,"✓ Ready","⏳ "&SUMPRODUCT(($A$6:$A$400<>"")*ISNUMBER(SEARCH($A$6:$A$400,K17))*($G$6:$G$400<>"Completed"))&" open")) -> ⏳ 1 open | Z17: =IF(A17="","",B17&"|"&COUNTIFS($B$6:B17,B17,$A$6:A17,"?*")) -> Phase 1|12 | AA17: =IF(OR(A17="",I17="",G17="Completed"),"",IF(I17>=StatusDate,I17+ROW()/100000,"")) -> 46309 | AB17: =IF(A17="","",IF(AND(G17<>"Completed",OR(G17="Blocked",AND(TRIM(P17)<>"",P17<>"None"))),ROW(),"")) | AC17: =IF(A17="","",IF(G17="Completed","Done",IF(G17="Blocked","Blocked",IF(X17="OVERDUE","Overdue",IF(AND(W17<>"",W17<=2),"Due soon",IF(AND(Y17<>"",LEFT(Y17,1)="⏳",G17<>"Not Started"),"Dependency open",IF(AND(S17<>"None",S17<>"",G17<>"Completed"),"External req.","On track"))))))) -> On track
... A64: P4-02 | B64: Phase 4 | C64: CPT Engine | D64: Issue fields: number, date, year, decade, PDF, access | E64: Meta fields: issue number, publication month/year, year & decade (auto-derived), PDF attachment, page count, access level (free / members / subscribers), featured articles. | F64: P0 | G64: Not Started | H64: 46316 | I64: 46316 | J64: 0 | K64: P4-01 | L64: Staging (Hostinger) | M64: inc/issue-meta.php | N64: Save issue; decade auto-calculates; invalid values rejected | O64: All issue metadata editable and validated | S64: None | T64: Not Tested | U64: =IF(A64="",0,IF(G64="Completed",1,IF(G64="Not Started",0,MIN(0.99,N(J64))))) -> 0 | V64: =IF(OR(A64="",H64="",I64=""),0,MAX(0,MIN(1,(StatusDate-H64+1)/(I64-H64+1)))) -> 0 | W64: =IF(OR(A64="",I64="",G64="Completed"),"",I64-StatusDate) -> 10 | X64: =IF(A64="","",IF(AND(G64<>"Completed",I64<>"",I64<StatusDate),"OVERDUE","")) | Y64: =IF(OR(A64="",K64=""),"",IF(SUMPRODUCT(($A$6:$A$400<>"")*ISNUMBER(SEARCH($A$6:$A$400,K64))*($G$6:$G$400<>"Completed"))=0,"✓ Ready","⏳ "&SUMPRODUCT(($A$6:$A$400<>"")*ISNUMBER(SEARCH($A$6:$A$400,K64))*($G$6:$G$400<>"Completed"))&" open")) -> ⏳ 1 open | Z64: =IF(A64="","",B64&"|"&COUNTIFS($B$6:B64,B64,$A$6:A64,"?*")) -> Phase 4|2 | AA64: =IF(OR(A64="",I64="",G64="Completed"),"",IF(I64>=StatusDate,I64+ROW()/100000,"")) -> 46316.001 | AB64: =IF(A64="","",IF(AND(G64<>"Completed",OR(G64="Blocked",AND(TRIM(P64)<>"",P64<>"None"))),ROW(),"")) | AC64: =IF(A64="","",IF(G64="Completed","Done",IF(G64="Blocked","Blocked",IF(X64="OVERDUE","Overdue",IF(AND(W64<>"",W64<=2),"Due soon",IF(AND(Y64<>"",LEFT(Y64,1)="⏳",G64<>"Not Started"),"Dependency open",IF(AND(S64<>"None",S64<>"",G64<>"Completed"),"External req.","On track"))))))) -> On track
A65: P4-03 | B65: Phase 4 | C65: Historical Assets | D65: Collect 48 historical issue PDFs, covers & manifest | E65: Request from client: all 48 PDFs, cover images and a manifest (issue number, date, title). Track missing items. | F65: P0 | G65: Not Started | H65: 46307 | I65: 46315 | J65: 0 | L65: External / Third-party | M65: url: shared drive | N65: Count received files = 48 PDFs + 48 covers; manifest complete | O65: All historical assets received and checked | S65: Historical Assets | T65: Not Tested | U65: =IF(A65="",0,IF(G65="Completed",1,IF(G65="Not Started",0,MIN(0.99,N(J65))))) -> 0 | V65: =IF(OR(A65="",H65="",I65=""),0,MAX(0,MIN(1,(StatusDate-H65+1)/(I65-H65+1)))) -> 0 | W65: =IF(OR(A65="",I65="",G65="Completed"),"",I65-StatusDate) -> 9 | X65: =IF(A65="","",IF(AND(G65<>"Completed",I65<>"",I65<StatusDate),"OVERDUE","")) | Y65: =IF(OR(A65="",K65=""),"",IF(SUMPRODUCT(($A$6:$A$400<>"")*ISNUMBER(SEARCH($A$6:$A$400,K65))*($G$6:$G$400<>"Completed"))=0,"✓ Ready","⏳ "&SUMPRODUCT(($A$6:$A$400<>"")*ISNUMBER(SEARCH($A$6:$A$400,K65))*($G$6:$G$400<>"Completed"))&" open")) | Z65: =IF(A65="","",B65&"|"&COUNTIFS($B$6:B65,B65,$A$6:A65,"?*")) -> Phase 4|3 | AA65: =IF(OR(A65="",I65="",G65="Completed"),"",IF(I65>=StatusDate,I65+ROW()/100000,"")) -> 46315.001 | AB65: =IF(A65="","",IF(AND(G65<>"Completed",OR(G65="Blocked",AND(TRIM(P65)<>"",P65<>"None"))),ROW(),"")) | AC65: =IF(A65="","",IF(G65="Completed","Done",IF(G65="Blocked","Blocked",IF(X65="OVERDUE","Overdue",IF(AND(W65<>"",W65<=2),"Due soon",IF(AND(Y65<>"",LEFT(Y65,1)="⏳",G65<>"Not Started"),"Dependency open",IF(AND(S65<>"None",S65<>"",G65<>"Completed"),"External req.","On track"))))))) -> External req.
A66: P4-04 | B66: Phase 4 | C66: Migration | D66: Historical issue migration (import 48 issues) | E66: CSV manifest + idempotent importer (WP-CLI via Hostinger SSH or one-time admin tool) creating issues, attaching covers and PDFs; re-runnable without duplicates. | F66: P0 | G66: Not Started | H66: 46316 | I66: 46316 | J66: 0 | K66: P4-02, P4-03 | L66: Staging (Hostinger) | M66: inc/issue-import.php, issues-manifest.csv | N66: Run import twice; still 48 issues; spot-check 10 | O66: All 48 issues imported with correct metadata, covers and PDFs | S66: Server Access | T66: Not Tested | U66: =IF(A66="",0,IF(G66="Completed",1,IF(G66="Not Started",0,MIN(0.99,N(J66))))) -> 0 | V66: =IF(OR(A66="",H66="",I66=""),0,MAX(0,MIN(1,(StatusDate-H66+1)/(I66-H66+1)))) -> 0 | W66: =IF(OR(A66="",I66="",G66="Completed"),"",I66-StatusDate) -> 10 | X66: =IF(A66="","",IF(AND(G66<>"Completed",I66<>"",I66<StatusDate),"OVERDUE","")) | Y66: =IF(OR(A66="",K66=""),"",IF(SUMPRODUCT(($A$6:$A$400<>"")*ISNUMBER(SEARCH($A$6:$A$400,K66))*($G$6:$G$400<>"Completed"))=0,"✓ Ready","⏳ "&SUMPRODUCT(($A$6:$A$400<>"")*ISNUMBER(SEARCH($A$6:$A$400,K66))*($G$6:$G$400<>"Completed"))&" open")) -> ⏳ 2 open | Z66: =IF(A66="","",B66&"|"&COUNTIFS($B$6:B66,B66,$A$6:A66,"?*")) -> Phase 4|4 | AA66: =IF(OR(A66="",I66="",G66="Completed"),"",IF(I66>=StatusDate,I66+ROW()/100000,"")) -> 46316.001 | AB66: =IF(A66="","",IF(AND(G66<>"Completed",OR(G66="Blocked",AND(TRIM(P66)<>"",P66<>"None"))),ROW(),"")) | AC66: =IF(A66="","",IF(G66="Completed","Done",IF(G66="Blocked","Blocked",IF(X66="OVERDUE","Overdue",IF(AND(W66<>"",W66<=2),"Due soon",IF(AND(Y66<>"",LEFT(Y66,1)="⏳",G66<>"Not Started"),"Dependency open",IF(AND(S66<>"None",S66<>"",G66<>"Completed"),"External req.","On track"))))))) -> External req.
A67: P4-05 | B67: Phase 4 | C67: Cover Images | D67: Cover image optimization | E67: Generate WebP and required sizes for covers; consistent aspect ratio. | F67: P1 | G67: Not Started | H67: 46316 | I67: 46316 | J67: 0 | K67: P4-04 | L67: Staging (Hostinger) | M67: inc/media.php | N67: Check archive weight and image dimensions | O67: Covers sharp and lightweight | S67: None | T67: Not Tested | U67: =IF(A67="",0,IF(G67="Completed",1,IF(G67="Not Started",0,MIN(0.99,N(J67))))) -> 0 | V67: =IF(OR(A67="",H67="",I67=""),0,MAX(0,MIN(1,(StatusDate-H67+1)/(I67-H67+1)))) -> 0 | W67: =IF(OR(A67="",I67="",G67="Completed"),"",I67-StatusDate) -> 10 | X67: =IF(A67="","",IF(AND(G67<>"Completed",I67<>"",I67<StatusDate),"OVERDUE","")) | Y67: =IF(OR(A67="",K67=""),"",IF(SUMPRODUCT(($A$6:$A$400<>"")*ISNUMBER(SEARCH($A$6:$A$400,K67))*($G$6:$G$400<>"Completed"))=0,"✓ Ready","⏳ "&SUMPRODUCT(($A$6:$A$400<>"")*ISNUMBER(SEARCH($A$6:$A$400,K67))*($G$6:$G$400<>"Completed"))&" open")) -> ⏳ 1 open | Z67: =IF(A67="","",B67&"|"&COUNTIFS($B$6:B67,B67,$A$6:A67,"?*")) -> Phase 4|5 | AA67: =IF(OR(A67="",I67="",G67="Completed"),"",IF(I67>=StatusDate,I67+ROW()/100000,"")) -> 46316.001 | AB67: =IF(A67="","",IF(AND(G67<>"Completed",OR(G67="Blocked",AND(TRIM(P67)<>"",P67<>"None"))),ROW(),"")) | AC67: =IF(A67="","",IF(G67="Completed","Done",IF(G67="Blocked","Blocked",IF(X67="OVERDUE","Overdue",IF(AND(W67<>"",W67<=2),"Due soon",IF(AND(Y67<>"",LEFT(Y67,1)="⏳",G67<>"Not Started"),"Dependency open",IF(AND(S67<>"None",S67<>"",G67<>"Completed"),"External req.","On track"))))))) -> On track
A68: P4-06 | B68: Phase 4 | C68: Issue Archive | D68: Issue archive template | E68: archive-magazine_issue.php: cover grid, newest first, issue number/date, pagination. | F68: P0 | G68: Not Started | H68: 46316 | I68: 46316 | J68: 0 | K68: P4-01 | L68: Staging (Hostinger) | M68: archive-magazine_issue.php, template-parts/issue/card.php | N68: Open archive; check ordering and pagination | O68: Archive lists all issues correctly | S68: None | T68: Not Tested | U68: =IF(A68="",0,IF(G68="Completed",1,IF(G68="Not Started",0,MIN(0.99,N(J68))))) -> 0 | V68: =IF(OR(A68="",H68="",I68=""),0,MAX(0,MIN(1,(StatusDate-H68+1)/(I68-H68+1)))) -> 0 | W68: =IF(OR(A68="",I68="",G68="Completed"),"",I68-StatusDate) -> 10 | X68: =IF(A68="","",IF(AND(G68<>"Completed",I68<>"",I68<StatusDate),"OVERDUE","")) | Y68: =IF(OR(A68="",K68=""),"",IF(SUMPRODUCT(($A$6:$A$400<>"")*ISNUMBER(SEARCH($A$6:$A$400,K68))*($G$6:$G$400<>"Completed"))=0,"✓ Ready","⏳ "&SUMPRODUCT(($A$6:$A$400<>"")*ISNUMBER(SEARCH($A$6:$A$400,K68))*($G$6:$G$400<>"Completed"))&" open")) -> ⏳ 1 open | Z68: =IF(A68="","",B68&"|"&COUNTIFS($B$6:B68,B68,$A$6:A68,"?*")) -> Phase 4|6 | AA68: =IF(OR(A68="",I68="",G68="Completed"),"",IF(I68>=StatusDate,I68+ROW()/100000,"")) -> 46316.001 | AB68: =IF(A68="","",IF(AND(G68<>"Completed",OR(G68="Blocked",AND(TRIM(P68)<>"",P68<>"None"))),ROW(),"")) | AC68: =IF(A68="","",IF(G68="Completed","Done",IF(G68="Blocked","Blocked",IF(X68="OVERDUE","Overdue",IF(AND(W68<>"",W68<=2),"Due soon",IF(AND(Y68<>"",LEFT(Y68,1)="⏳",G68<>"Not Started"),"Dependency open",IF(AND(S68<>"None",S68<>"",G68<>"Completed"),"External req.","On track"))))))) -> On track
A69: P4-07 | B69: Phase 4 | C69: Issue Archive | D69: Year & decade filtering | E69: Filter issues by decade then year (query vars + optional AJAX), crawlable URLs. | F69: P1 | G69: Not Started | H69: 46316 | I69: 46316 | J69: 0 | K69: P4-06 | L69: Staging (Hostinger) | M69: archive-magazine_issue.php, assets/js/modules/issue-filter.js | N69: Filter each decade/year; counts match manifest | O69: Filters return correct issues | S69: None | T69: Not Tested | U69: =IF(A69="",0,IF(G69="Completed",1,IF(G69="Not Started",0,MIN(0.99,N(J69))))) -> 0 | V69: =IF(OR(A69="",H69="",I69=""),0,MAX(0,MIN(1,(StatusDate-H69+1)/(I69-H69+1)))) -> 0 | W69: =IF(OR(A69="",I69="",G69="Completed"),"",I69-StatusDate) -> 10 | X69: =IF(A69="","",IF(AND(G69<>"Completed",I69<>"",I69<StatusDate),"OVERDUE","")) | Y69: =IF(OR(A69="",K69=""),"",IF(SUMPRODUCT(($A$6:$A$400<>"")*ISNUMBER(SEARCH($A$6:$A$400,K69))*($G$6:$G$400<>"Completed"))=0,"✓ Ready","⏳ "&SUMPRODUCT(($A$6:$A$400<>"")*ISNUMBER(SEARCH($A$6:$A$400,K69))*($G$6:$G$400<>"Completed"))&" open")) -> ⏳ 1 open | Z69: =IF(A69="","",B69&"|"&COUNTIFS($B$6:B69,B69,$A$6:A69,"?*")) -> Phase 4|7 | AA69: =IF(OR(A69="",I69="",G69="Completed"),"",IF(I69>=StatusDate,I69+ROW()/100000,"")) -> 46316.001 | AB69: =IF(A69="","",IF(AND(G69<>"Completed",OR(G69="Blocked",AND(TRIM(P69)<>"",P69<>"None"))),ROW(),"")) | AC69: =IF(A69="","",IF(G69="Completed","Done",IF(G69="Blocked","Blocked",IF(X69="OVERDUE","Overdue",IF(AND(W69<>"",W69<=2),"Due soon",IF(AND(Y69<>"",LEFT(Y69,1)="⏳",G69<>"Not Started"),"Dependency open",IF(AND(S69<>"None",S69<>"",G69<>"Completed"),"External req.","On track"))))))) -> On track
A70: P4-08 | B70: Phase 4 | C70: Single Issue | D70: Single issue page | E70: single-magazine_issue.php: large cover, issue details, highlights/table of contents, read & download actions, previous/next issue. | F70: P0 | G70: Not Started | H70: 46317 | I70: 46317 | J70: 0 | K70: P4-02 | L70: Staging (Hostinger) | M70: single-magazine_issue.php | N70: Open 5 issues incl. oldest and newest | O70: Single issue page complete for every issue | S70: None | T70: Not Tested | U70: =IF(A70="",0,IF(G70="Completed",1,IF(G70="Not Started",0,MIN(0.99,N(J70))))) -> 0 | V70: =IF(OR(A70="",H70="",I70=""),0,MAX(0,MIN(1,(StatusDate-H70+1)/(I70-H70+1)))) -> 0 | W70: =IF(OR(A70="",I70="",G70="Completed"),"",I70-StatusDate) -> 11 | X70: =IF(A70="","",IF(AND(G70<>"Completed",I70<>"",I70<StatusDate),"OVERDUE","")) | Y70: =IF(OR(A70="",K70=""),"",IF(SUMPRODUCT(($A$6:$A$400<>"")*ISNUMBER(SEARCH($A$6:$A$400,K70))*($G$6:$G$400<>"Completed"))=0,"✓ Ready","⏳ "&SUMPRODUCT(($A$6:$A$400<>"")*ISNUMBER(SEARCH($A$6:$A$400,K70))*($G$6:$G$400<>"Completed"))&" open")) -> ⏳ 1 open | Z70: =IF(A70="","",B70&"|"&COUNTIFS($B$6:B70,B70,$A$6:A70,"?*")) -> Phase 4|8 | AA70: =IF(OR(A70="",I70="",G70="Completed"),"",IF(I70>=StatusDate,I70+ROW()/100000,"")) -> 46317.001 | AB70: =IF(A70="","",IF(AND(G70<>"Completed",OR(G70="Blocked",AND(TRIM(P70)<>"",P70<>"None"))),ROW(),"")) | AC70: =IF(A70="","",IF(G70="Completed","Done",IF(G70="Blocked","Blocked",IF(X70="OVERDUE","Overdue",IF(AND(W70<>"",W70<=2),"Due soon",IF(AND(Y70<>"",LEFT(Y70,1)="⏳",G70<>"Not Started"),"Dependency open",IF(AND(S70<>"None",S70<>"",G70<>"Completed"),"External req.","On track"))))))) -> On track
A71: P4-09 | B71: Phase 4 | C71: Flipbook | D71: Flipbook reader | E71: Self-hosted PDF.js based flipbook, lazy-loaded only on issue pages, page navigation, zoom, fullscreen; mobile fallback to scroll view. | F71: P1 | G71: Not Started | H71: 46317 | I71: 46317 | J71: 0 | K71: P4-08 | L71: Staging (Hostinger) | M71: assets/js/modules/flipbook.js, assets/vendor/pdfjs/* | N71: Open large PDF on mobile & desktop; measure load time | O71: Readable flipbook on desktop & mobile without blocking page load | S71: None | T71: Not Tested | U71: =IF(A71="",0,IF(G71="Completed",1,IF(G71="Not Started",0,MIN(0.99,N(J71))))) -> 0 | V71: =IF(OR(A71="",H71="",I71=""),0,MAX(0,MIN(1,(StatusDate-H71+1)/(I71-H71+1)))) -> 0 | W71: =IF(OR(A71="",I71="",G71="Completed"),"",I71-StatusDate) -> 11 | X71: =IF(A71="","",IF(AND(G71<>"Completed",I71<>"",I71<StatusDate),"OVERDUE","")) | Y71: =IF(OR(A71="",K71=""),"",IF(SUMPRODUCT(($A$6:$A$400<>"")*ISNUMBER(SEARCH($A$6:$A$400,K71))*($G$6:$G$400<>"Completed"))=0,"✓ Ready","⏳ "&SUMPRODUCT(($A$6:$A$400<>"")*ISNUMBER(SEARCH($A$6:$A$400,K71))*($G$6:$G$400<>"Completed"))&" open")) -> ⏳ 1 open | Z71: =IF(A71="","",B71&"|"&COUNTIFS($B$6:B71,B71,$A$6:A71,"?*")) -> Phase 4|9 | AA71: =IF(OR(A71="",I71="",G71="Completed"),"",IF(I71>=StatusDate,I71+ROW()/100000,"")) -> 46317.001 | AB71: =IF(A71="","",IF(AND(G71<>"Completed",OR(G71="Blocked",AND(TRIM(P71)<>"",P71<>"None"))),ROW(),"")) | AC71: =IF(A71="","",IF(G71="Completed","Done",IF(G71="Blocked","Blocked",IF(X71="OVERDUE","Overdue",IF(AND(W71<>"",W71<=2),"Due soon",IF(AND(Y71<>"",LEFT(Y71,1)="⏳",G71<>"Not Started"),"Dependency open",IF(AND(S71<>"None",S71<>"",G71<>"Completed"),"External req.","On track"))))))) -> On track
A72: P4-10 | B72: Phase 4 | C72: PDF Downloads | D72: Secure PDF downloads | E72: Download endpoint with nonce and access check, download counter, correct filename/headers. | F72: P0 | G72: Not Started | H72: 46317 | I72: 46317 | J72: 0 | K72: P4-08 | L72: Staging (Hostinger) | M72: inc/pdf-download.php | N72: Download as guest/member/subscriber; check headers | O72: Downloads work and respect access rules | S72: None | T72: Not Tested | U72: =IF(A72="",0,IF(G72="Completed",1,IF(G72="Not Started",0,MIN(0.99,N(J72))))) -> 0 | V72: =IF(OR(A72="",H72="",I72=""),0,MAX(0,MIN(1,(StatusDate-H72+1)/(I72-H72+1)))) -> 0 | W72: =IF(OR(A72="",I72="",G72="Completed"),"",I72-StatusDate) -> 11 | X72: =IF(A72="","",IF(AND(G72<>"Completed",I72<>"",I72<StatusDate),"OVERDUE","")) | Y72: =IF(OR(A72="",K72=""),"",IF(SUMPRODUCT(($A$6:$A$400<>"")*ISNUMBER(SEARCH($A$6:$A$400,K72))*($G$6:$G$400<>"Completed"))=0,"✓ Ready","⏳ "&SUMPRODUCT(($A$6:$A$400<>"")*ISNUMBER(SEARCH($A$6:$A$400,K72))*($G$6:$G$400<>"Completed"))&" open")) -> ⏳ 1 open | Z72: =IF(A72="","",B72&"|"&COUNTIFS($B$6:B72,B72,$A$6:A72,"?*")) -> Phase 4|10 | AA72: =IF(OR(A72="",I72="",G72="Completed"),"",IF(I72>=StatusDate,I72+ROW()/100000,"")) -> 46317.001 | AB72: =IF(A72="","",IF(AND(G72<>"Completed",OR(G72="Blocked",AND(TRIM(P72)<>"",P72<>"None"))),ROW(),"")) | AC72: =IF(A72="","",IF(G72="Completed","Done",IF(G72="Blocked","Blocked",IF(X72="OVERDUE","Overdue",IF(AND(W72<>"",W72<=2),"Due soon",IF(AND(Y72<>"",LEFT(Y72,1)="⏳",G72<>"Not Started"),"Dependency open",IF(AND(S72<>"None",S72<>"",G72<>"Completed"),"External req.","On track"))))))) -> On track
